Traceback (most recent call last):
  File "/Users/jk8sd/.pyenv/versions/3.12.5/lib/python3.12/site-packages/jupyter_cache/executors/utils.py", line 58, in single_nb_execution
    executenb(
  File "/Users/jk8sd/.pyenv/versions/3.12.5/lib/python3.12/site-packages/nbclient/client.py", line 1314, in execute
    return NotebookClient(nb=nb, resources=resources, km=km, **kwargs).execute()
           ^^^^^^^^^^^^^^^^^^^^^^^^^^^^^^^^^^^^^^^^^^^^^^^^^^^^^^^^^^^^^^^^^^^^^
  File "/Users/jk8sd/.pyenv/versions/3.12.5/lib/python3.12/site-packages/jupyter_core/utils/__init__.py", line 165, in wrapped
    return loop.run_until_complete(inner)
           ^^^^^^^^^^^^^^^^^^^^^^^^^^^^^^
  File "/Users/jk8sd/.pyenv/versions/3.12.5/lib/python3.12/asyncio/base_events.py", line 687, in run_until_complete
    return future.result()
           ^^^^^^^^^^^^^^^
  File "/Users/jk8sd/.pyenv/versions/3.12.5/lib/python3.12/site-packages/nbclient/client.py", line 709, in async_execute
    await self.async_execute_cell(
  File "/Users/jk8sd/.pyenv/versions/3.12.5/lib/python3.12/site-packages/nbclient/client.py", line 1062, in async_execute_cell
    await self._check_raise_for_error(cell, cell_index, exec_reply)
  File "/Users/jk8sd/.pyenv/versions/3.12.5/lib/python3.12/site-packages/nbclient/client.py", line 918, in _check_raise_for_error
    raise CellExecutionError.from_cell_and_msg(cell, exec_reply_content)
nbclient.exceptions.CellExecutionError: An error occurred while executing the following cell:
------------------
dbserver = psycopg.connect(
    user='postgres', 
    password=pgpassword, 
    host='localhost'
)
dbserver.autocommit = True
cursor = dbserver.cursor()
------------------


[0;31m---------------------------------------------------------------------------[0m
[0;31mOperationalError[0m                          Traceback (most recent call last)
Cell [0;32mIn[5], line 1[0m
[0;32m----> 1[0m dbserver [38;5;241m=[39m [43mpsycopg[49m[38;5;241;43m.[39;49m[43mconnect[49m[43m([49m
[1;32m      2[0m [43m    [49m[43muser[49m[38;5;241;43m=[39;49m[38;5;124;43m'[39;49m[38;5;124;43mpostgres[39;49m[38;5;124;43m'[39;49m[43m,[49m[43m [49m
[1;32m      3[0m [43m    [49m[43mpassword[49m[38;5;241;43m=[39;49m[43mpgpassword[49m[43m,[49m[43m [49m
[1;32m      4[0m [43m    [49m[43mhost[49m[38;5;241;43m=[39;49m[38;5;124;43m'[39;49m[38;5;124;43mlocalhost[39;49m[38;5;124;43m'[39;49m
[1;32m      5[0m [43m)[49m
[1;32m      6[0m dbserver[38;5;241m.[39mautocommit [38;5;241m=[39m [38;5;28;01mTrue[39;00m
[1;32m      7[0m cursor [38;5;241m=[39m dbserver[38;5;241m.[39mcursor()

File [0;32m~/.pyenv/versions/3.12.5/lib/python3.12/site-packages/psycopg/connection.py:119[0m, in [0;36mConnection.connect[0;34m(cls, conninfo, autocommit, prepare_threshold, context, row_factory, cursor_factory, **kwargs)[0m
[1;32m    117[0m [38;5;28;01mif[39;00m [38;5;129;01mnot[39;00m rv:
[1;32m    118[0m     [38;5;28;01massert[39;00m last_ex
[0;32m--> 119[0m     [38;5;28;01mraise[39;00m last_ex[38;5;241m.[39mwith_traceback([38;5;28;01mNone[39;00m)
[1;32m    121[0m rv[38;5;241m.[39m_autocommit [38;5;241m=[39m [38;5;28mbool[39m(autocommit)
[1;32m    122[0m [38;5;28;01mif[39;00m row_factory:

[0;31mOperationalError[0m: connection failed: connection to server at "::1", port 5432 failed: could not receive data from server: Connection refused

